Workbook

Sheet Start Here
A1: IAMONIT Project Control Workbook
A2: Jira-style sprint board + dependencies/timeline + IntelliJ-ready coding tasks
A4: What this workbook gives you
A5: A practical replacement for Jira: backlog, sprint board, timeline, dependencies, architecture, coding tasks by file/class, API, DB, risks, and release checklist.
A8: How to use it
A9: Start from Dashboard, then manage work in Sprint Board and Backlog. Use Dependencies & Timeline before assigning sprint dates. Use IntelliJ Coding Tasks when you are ready to code file-by-file.
A12: Suggested stack
A13: Next.js + Tailwind frontend, NestJS backend, PostgreSQL/Supabase, Supabase Storage/S3, JWT/RLS, Vercel + Railway/Render/AWS deployment.
A16: Status values
A17: Todo, In Progress, Blocked, Review, Done

Sheet Dashboard
A1: Project Dashboard
A2: High-level project health, sprint progress, and delivery controls
A4: Total Tasks | D4: Done | G4: In Progress
A5: =COUNTA(Backlog!A2:A500) -> 70 | D5: =COUNTIF(Backlog!F2:F500,"Done") -> 11 | G5: =COUNTIF(Backlog!F2:F500,"In Progress") -> 1
A7: Blocked | D7: Total Points | G7: Done Points
A8: =COUNTIF(Backlog!F2:F500,"Blocked") -> 0 | D8: =SUM(Backlog!E2:E500) -> 369 | G8: =SUMIF(Backlog!F2:F500,"Done",Backlog!E2:E500) -> 45
A11: Sprint | B11: Tasks | C11: Done | D11: Blocked | E11: Points | F11: Completion % | H11: Status | I11: Count
A12: Sprint 1 | B12: =COUNTIF(Backlog!K:K,A12) -> 9 | C12: =COUNTIFS(Backlog!K:K,A12,Backlog!F:F,"Done") -> 8 | D12: =COUNTIFS(Backlog!K:K,A12,Backlog!F:F,"Blocked") -> 0 | E12: =SUMIF(Backlog!K:K,A12,Backlog!E:E) -> 35 | F12: =IF(B12=0,0,C12/B12) -> 0.88888889 | H12: Todo | I12: =COUNTIF(Backlog!F:F,H12) -> 61
A13: Sprint 2 | B13: =COUNTIF(Backlog!K:K,A13) -> 9 | C13: =COUNTIFS(Backlog!K:K,A13,Backlog!F:F,"Done") -> 1 | D13: =COUNTIFS(Backlog!K:K,A13,Backlog!F:F,"Blocked") -> 0 | E13: =SUMIF(Backlog!K:K,A13,Backlog!E:E) -> 47 | F13: =IF(B13=0,0,C13/B13) -> 0.11111111 | H13: In Progress | I13: =COUNTIF(Backlog!F:F,H13) -> 1
A14: Sprint 3 | B14: =COUNTIF(Backlog!K:K,A14) -> 7 | C14: =COUNTIFS(Backlog!K:K,A14,Backlog!F:F,"Done") -> 0 | D14: =COUNTIFS(Backlog!K:K,A14,Backlog!F:F,"Blocked") -> 0 | E14: =SUMIF(Backlog!K:K,A14,Backlog!E:E) -> 31 | F14: =IF(B14=0,0,C14/B14) -> 0 | H14: Blocked | I14: =COUNTIF(Backlog!F:F,H14) -> 0
A15: Sprint 4 | B15: =COUNTIF(Backlog!K:K,A15) -> 10 | C15: =COUNTIFS(Backlog!K:K,A15,Backlog!F:F,"Done") -> 0 | D15: =COUNTIFS(Backlog!K:K,A15,Backlog!F:F,"Blocked") -> 0 | E15: =SUMIF(Backlog!K:K,A15,Backlog!E:E) -> 58 | F15: =IF(B15=0,0,C15/B15) -> 0 | H15: Review | I15: =COUNTIF(Backlog!F:F,H15) -> 0
A16: Sprint 5 | B16: =COUNTIF(Backlog!K:K,A16) -> 8 | C16: =COUNTIFS(Backlog!K:K,A16,Backlog!F:F,"Done") -> 0 | D16: =COUNTIFS(Backlog!K:K,A16,Backlog!F:F,"Blocked") -> 0 | E16: =SUMIF(Backlog!K:K,A16,Backlog!E:E) -> 53 | F16: =IF(B16=0,0,C16/B16) -> 0 | H16: Done | I16: =COUNTIF(Backlog!F:F,H16) -> 11
A17: Sprint 6 | B17: =COUNTIF(Backlog!K:K,A17) -> 8 | C17: =COUNTIFS(Backlog!K:K,A17,Backlog!F:F,"Done") -> 0 | D17: =COUNTIFS(Backlog!K:K,A17,Backlog!F:F,"Blocked") -> 0 | E17: =SUMIF(Backlog!K:K,A17,Backlog!E:E) -> 34 | F17: =IF(B17=0,0,C17/B17) -> 0
A18: Sprint 7 | B18: =COUNTIF(Backlog!K:K,A18) -> 7 | C18: =COUNTIFS(Backlog!K:K,A18,Backlog!F:F,"Done") -> 0 | D18: =COUNTIFS(Backlog!K:K,A18,Backlog!F:F,"Blocked") -> 0 | E18: =SUMIF(Backlog!K:K,A18,Backlog!E:E) -> 47 | F18: =IF(B18=0,0,C18/B18) -> 0
A19: Sprint 8 | B19: =COUNTIF(Backlog!K:K,A19) -> 7 | C19: =COUNTIFS(Backlog!K:K,A19,Backlog!F:F,"Done") -> 0 | D19: =COUNTIFS(Backlog!K:K,A19,Backlog!F:F,"Blocked") -> 0 | E19: =SUMIF(Backlog!K:K,A19,Backlog!E:E) -> 27 | F19: =IF(B19=0,0,C19/B19) -> 0
A20: Sprint 9 | B20: =COUNTIF(Backlog!K:K,A20) -> 5 | C20: =COUNTIFS(Backlog!K:K,A20,Backlog!F:F,"Done") -> 0 | D20: =COUNTIFS(Backlog!K:K,A20,Backlog!F:F,"Blocked") -> 0 | E20: =SUMIF(Backlog!K:K,A20,Backlog!E:E) -> 26 | F20: =IF(B20=0,0,C20/B20) -> 0

Sheet Backlog
A1: Task ID | B1: Epic | C1: Title | D1: Priority | E1: Story Points | F1: Status | G1: Description | H1: Acceptance Criteria | I1: Owner Role | J1: Start Date | K1: Sprint | L1: Duration Days | M1: End Date | N1: Dependencies | O1: Files / Classes | P1: Notes
A2: IAM-001 | B2: Project Setup | C2: Initialize Git repositories | D2: Critical | E2: 3 | F2: Done | G2: Create mono-repo or two repos for frontend/backend with branch rules. | H2: Repos created; README exists; main/dev branches; .gitignore committed | I2: DevOps | J2: 46153 | K2: Sprint 1 | L2: 1 | M2: 46153 | O2: /README.md; /.gitignore
A3: IAM-002 | B3: Project Setup | C3: Create Next.js app | D3: Critical | E3: 5 | F3: Done | G3: Initialize the Next.js frontend under apps/web using TypeScript, App Router, Tailwind CSS, and ESLint as part of the existing pnpm workspace. | H3: apps/web/package.json exists; TypeScript is configured; App Router is configured; Tailwind CSS is configured; ESLint is configured; apps/web/app/layout.tsx exists; apps/web/app/page.tsx exists; the package participates in the existing pnpm workspace; the existing root dev:web command works with the web package; pnpm --filter <web-package> build passes | I3: Frontend | J3: 46153 | K3: Sprint 1 | L3: 2 | M3: 46154 | N3: IAM-001 | O3: apps/web/package.json; apps/web/app/layout.tsx; apps/web/tailwind.config.ts
A4: IAM-003 | B4: Project Setup | C4: Create NestJS backend | D4: Critical | E4: 5 | F4: Done | G4: Initialize NestJS TypeScript API service with modules folder. | H4: API starts locally; health endpoint returns OK; Swagger enabled | I4: Backend | J4: 46153 | K4: Sprint 1 | L4: 2 | M4: 46154 | N4: IAM-001 | O4: apps/api/src/main.ts; apps/api/src/app.module.ts
A5: IAM-004 | B5: Project Setup | C5: Configure environment management | D5: High | E5: 3 | F5: Done | G5: Create .env examples and config validation for frontend/backend. | H5: No secrets committed; env schema validates required values | I5: DevOps | J5: 46154 | K5: Sprint 1 | L5: 1 | M5: 46154 | N5: IAM-002,IAM-003 | O5: apps/api/src/config/env.ts; apps/web/.env.example
A6: IAM-005 | B6: Project Setup | C6: Setup code quality tools | D6: High | E6: 3 | F6: Todo | G6: Add ESLint, Prettier, lint scripts, formatting rules. | H6: npm run lint passes; consistent formatting | I6: DevOps | J6: 46154 | K6: Sprint 1 | L6: 1 | M6: 46154 | N6: IAM-002,IAM-003 | O6: apps/web/.eslintrc; apps/api/.eslintrc
A7: IAM-006 | B7: Database Foundation | C7: Create Supabase project | D7: Critical | E7: 3 | F7: Done | G7: Provision Supabase project and connection settings. | H7: DB reachable; connection string configured; local migration flow documented | I7: Database | J7: 46155 | K7: Sprint 1 | L7: 1 | M7: 46155 | N7: IAM-004 | O7: supabase/config.toml
A8: IAM-007 | B8: Database Foundation | C8: Create base audit trigger | D8: High | E8: 5 | F8: Done | G8: Add timestamptz audit fields and reusable trigger function. | H8: created_at/updated_at use timestamptz; trigger tested | I8: Database | J8: 46155 | K8: Sprint 1 | L8: 2 | M8: 46156 | N8: IAM-006 | O8: supabase/migrations/001_audit.sql
A9: IAM-008 | B9: Auth | C9: Build auth DTOs and validation | D9: High | E9: 3 | F9: Done | G9: Create register/login DTOs with validation rules. | H9: Invalid payloads rejected; password/email rules enforced | I9: Backend | J9: 46156 | K9: Sprint 1 | L9: 1 | M9: 46156 | N9: IAM-003 | O9: apps/api/src/modules/auth/dto/register.dto.ts; login.dto.ts
A10: IAM-009 | B10: Auth | C10: Auth UI shell | D10: High | E10: 5 | F10: Done | G10: Create login/register pages with role selection. | H10: User can navigate between login/register; form validation visible | I10: Frontend | J10: 46156 | K10: Sprint 1 | L10: 2 | M10: 46157 | N10: IAM-002 | O10: apps/web/app/(auth)/login/page.tsx; apps/web/app/(auth)/register/page.tsx
A11: IAM-010 | B11: Multi-Tenant Schema | C11: Create tenants table | D11: Critical | E11: 5 | F11: Done | G11: Create tenants table with audit fields and unique name constraints. | H11: Migration applies; tenant can be inserted; RLS enabled | I11: Database | J11: 46158 | K11: Sprint 2 | L11: 1 | M11: 46158 | N11: IAM-007 | O11: supabase/migrations/010_tenants.sql
A12: IAM-011 | B12: Multi-Tenant Schema | C12: Create app_users table | D12: Critical | E12: 5 | F12: Done | G12: Create app user profile linked to Supabase auth.users. | H12: User profile linked to auth ID; role column constrained | I12: Database | J12: 46158 | K12: Sprint 2 | L12: 1 | M12: 46158 | N12: IAM-010 | O12: supabase/migrations/011_users.sql
A13: IAM-012 | B13: Multi-Tenant Schema | C13: Create transporter profiles table | D13: High | E13: 3 | F13: Todo | G13: Store company/dispatch/broker information by tenant. | H13: Profile belongs to tenant; audit fields exist | I13: Database | J13: 46159 | K13: Sprint 2 | L13: 1 | M13: 46159 | N13: IAM-010 | O13: supabase/migrations/012_transporter_profiles.sql
A14: IAM-013 | B14: Multi-Tenant Schema | C14: Create car puller profiles table | D14: High | E14: 3 | F14: Todo | G14: Store car puller name/photo/logo/phone details. | H14: Profile belongs to tenant/user; photo_url/logo_url supported | I14: Database | J14: 46159 | K14: Sprint 2 | L14: 1 | M14: 46159 | N14: IAM-011 | O14: supabase/migrations/013_car_puller_profiles.sql
... A71: IAM-070 | B71: Real-Time | C71: Add live notification updates | D71: Low | E71: 5 | F71: Todo | G71: Unread notifications update in real-time. | H71: Notification bell updates without refresh | I71: Fullstack | J71: 46215 | K71: Sprint 9 | L71: 2 | M71: 46216 | N71: IAM-047,IAM-069 | O71: apps/web/components/notifications/NotificationBell.tsx
A72: IAM-071 | B72: Developer Automation | C72: Establish Excel-driven Codex agent foundation | D72: High | E72: 3 | F72: In Progress | G72: Establish repository instructions, tracker rules, and the package location for an Excel-driven Codex task agent. | H72: AGENTS.md contains the agent rules; Excel temporary files are ignored; the workbook contains IAM-071 and CODE-041; completed tasks are not selected again; no commits occur without a task ID. | I72: DevOps | J72: 46230 | K72: Sprint 10 | L72: 1 | M72: 46230 | N72: IAM-001,IAM-003 | O72: AGENTS.md; .gitignore; planning/IAMONIT_Full_Project_Control_Workbook.xlsx | P72: Every Git commit must begin with the exact related task ID.
A73: IAM-072 | B73: Developer Automation | C73: Align tracker paths with workspace structure | D73: High | E73: 3 | F73: Done | G73: Align legacy backend and frontend file paths in the IAMONIT project tracker with the repository’s pnpm workspace structure. | H73: Legacy backend paths use apps/api; legacy frontend paths use apps/web; canonical paths remain unchanged; no formulas, dropdowns, styles, or unrelated tracker content are damaged; remaining invalid path prefixes are reported. | I73: DevOps | J73: 46230 | K73: Sprint 10 | L73: 1 | M73: 46230 | N73: IAM-071 | O73: planning/IAMONIT_Full_Project_Control_Workbook.xlsx | P73: Normalize path-bearing tracker cells only. Do not change descriptive prose, URLs, package names, commands, class names, or task IDs.
A74: IAM-073 | B74: Developer Automation | C74: Add controlled Codex execution pipeline | D74: High | E74: 5 | F74: Done | G74: Extend the IAMONIT task-agent so it can generate a task-specific Codex prompt and invoke Codex non-interactively under explicit safety controls. | H74: The agent supports a non-mutating plan mode; execution requires an explicit flag; execution is blocked on a dirty working tree or protected branch; Codex runs only inside the repository workspace; results and exit status are captured; the workbook is never modified; no commit or push occurs automatically. | I74: DevOps | J74: 46230 | K74: Sprint 10 | L74: 2 | M74: 46231 | N74: IAM-071,IAM-072 | O74: packages/task-agent/src/prompt-builder.ts; packages/task-agent/src/codex-executor.ts; packages/task-agent/src/git-preflight.ts; packages/task-agent/src/cli.ts | P74: Plan mode is the default. Real execution requires explicit user action and must stop at human review.

Sheet Sprint Board
A1: Sprint | B1: Task ID | C1: Epic | D1: Title | E1: Owner | F1: Priority | G1: Points | H1: Status | I1: Dependencies | J1: Acceptance Criteria
A2: Sprint 1 | B2: IAM-001 | C2: Project Setup | D2: Initialize Git repositories | E2: DevOps | F2: Critical | G2: 3 | H2: Done | J2: Repos created; README exists; main/dev branches; .gitignore committed
A3: Sprint 1 | B3: IAM-002 | C3: Project Setup | D3: Create Next.js app | E3: Frontend | F3: Critical | G3: 5 | H3: Done | I3: IAM-001 | J3: apps/web/package.json exists; TypeScript is configured; App Router is configured; Tailwind CSS is configured; ESLint is configured; apps/web/app/layout.tsx exists; apps/web/app/page.tsx exists; the package participates in the existing pnpm workspace; the existing root dev:web command works with the web package; pnpm --filter <web-package> build passes
A4: Sprint 1 | B4: IAM-003 | C4: Project Setup | D4: Create NestJS backend | E4: Backend | F4: Critical | G4: 5 | H4: Done | I4: IAM-001 | J4: API starts locally; health endpoint returns OK; Swagger enabled
A5: Sprint 1 | B5: IAM-004 | C5: Project Setup | D5: Configure environment management | E5: DevOps | F5: High | G5: 3 | H5: Done | I5: IAM-002,IAM-003 | J5: No secrets committed; env schema validates required values
A6: Sprint 1 | B6: IAM-005 | C6: Project Setup | D6: Setup code quality tools | E6: DevOps | F6: High | G6: 3 | H6: Todo | I6: IAM-002,IAM-003 | J6: npm run lint passes; consistent formatting
A7: Sprint 1 | B7: IAM-006 | C7: Database Foundation | D7: Create Supabase project | E7: Database | F7: Critical | G7: 3 | H7: Done | I7: IAM-004 | J7: DB reachable; connection string configured; local migration flow documented
A8: Sprint 1 | B8: IAM-007 | C8: Database Foundation | D8: Create base audit trigger | E8: Database | F8: High | G8: 5 | H8: Done | I8: IAM-006 | J8: created_at/updated_at use timestamptz; trigger tested
A9: Sprint 1 | B9: IAM-008 | C9: Auth | D9: Build auth DTOs and validation | E9: Backend | F9: High | G9: 3 | H9: Done | I9: IAM-003 | J9: Invalid payloads rejected; password/email rules enforced
A10: Sprint 1 | B10: IAM-009 | C10: Auth | D10: Auth UI shell | E10: Frontend | F10: High | G10: 5 | H10: Done | I10: IAM-002 | J10: User can navigate between login/register; form validation visible
A11: Sprint 2 | B11: IAM-010 | C11: Multi-Tenant Schema | D11: Create tenants table | E11: Database | F11: Critical | G11: 5 | H11: Done | I11: IAM-007 | J11: Migration applies; tenant can be inserted; RLS enabled
A12: Sprint 2 | B12: IAM-011 | C12: Multi-Tenant Schema | D12: Create app_users table | E12: Database | F12: Critical | G12: 5 | H12: Done | I12: IAM-010 | J12: User profile linked to auth ID; role column constrained
A13: Sprint 2 | B13: IAM-012 | C13: Multi-Tenant Schema | D13: Create transporter profiles table | E13: Database | F13: High | G13: 3 | H13: Todo | I13: IAM-010 | J13: Profile belongs to tenant; audit fields exist
A14: Sprint 2 | B14: IAM-013 | C14: Multi-Tenant Schema | D14: Create car puller profiles table | E14: Database | F14: High | G14: 3 | H14: Todo | I14: IAM-011 | J14: Profile belongs to tenant/user; photo_url/logo_url supported
... A74: Sprint 10 | B74: IAM-073 | C74: Developer Automation | D74: Add controlled Codex execution pipeline | E74: DevOps | F74: High | G74: 5 | H74: Done | I74: IAM-071,IAM-072 | J74: The task-agent can safely prepare and explicitly launch one Codex coding task without committing, pushing, or updating the workbook.

Sheet Timeline + Gantt
A1: Task ID | B1: Title | C1: Sprint | D1: Start | E1: End | F1: Duration | G1: Status | H1: Dependencies | I1: 05/11 | J1: 05/12 | K1: 05/13 | L1: 05/14 | M1: 05/15 | N1: 05/16 | O1: 05/17 | P1: 05/18 | Q1: 05/19 | R1: 05/20 | S1: 05/21 | T1: 05/22 | U1: 05/23 | V1: 05/24 | W1: 05/25 | X1: 05/26 | Y1: 05/27 | Z1: 05/28 | AA1: 05/29 | AB1: 05/30 | AC1: 05/31 | AD1: 06/01 | AE1: 06/02 | AF1: 06/03 | AG1: 06/04 | AH1: 06/05 | AI1: 06/06 | AJ1: 06/07 | AK1: 06/08 | AL1: 06/09 | AM1: 06/10 | AN1: 06/11 | AO1: 06/12 | AP1: 06/13 | AQ1: 06/14 | AR1: 06/15 | AS1: 06/16 | AT1: 06/17 | AU1: 06/18 | AV1: 06/19 | AW1: 06/20 | AX1: 06/21
A2: IAM-001 | B2: Initialize Git repositories | C2: Sprint 1 | D2: 46153 | E2: 46153 | F2: 1 | G2: Todo | I2: ■
A3: IAM-002 | B3: Create Next.js app | C3: Sprint 1 | D3: 46153 | E3: 46154 | F3: 2 | G3: Todo | H3: IAM-001 | I3: ■ | J3: ■
A4: IAM-003 | B4: Create NestJS backend | C4: Sprint 1 | D4: 46153 | E4: 46154 | F4: 2 | G4: Todo | H4: IAM-001 | I4: ■ | J4: ■
A5: IAM-004 | B5: Configure environment management | C5: Sprint 1 | D5: 46154 | E5: 46154 | F5: 1 | G5: Todo | H5: IAM-002,IAM-003 | J5: ■
A6: IAM-005 | B6: Setup code quality tools | C6: Sprint 1 | D6: 46154 | E6: 46154 | F6: 1 | G6: Todo | H6: IAM-002,IAM-003 | J6: ■
A7: IAM-006 | B7: Create Supabase project | C7: Sprint 1 | D7: 46155 | E7: 46155 | F7: 1 | G7: Todo | H7: IAM-004 | K7: ■
A8: IAM-007 | B8: Create base audit trigger | C8: Sprint 1 | D8: 46155 | E8: 46156 | F8: 2 | G8: Todo | H8: IAM-006 | K8: ■ | L8: ■
A9: IAM-008 | B9: Build auth DTOs and validation | C9: Sprint 1 | D9: 46156 | E9: 46156 | F9: 1 | G9: Todo | H9: IAM-003 | L9: ■
A10: IAM-009 | B10: Auth UI shell | C10: Sprint 1 | D10: 46156 | E10: 46157 | F10: 2 | G10: Todo | H10: IAM-002 | L10: ■ | M10: ■
A11: IAM-010 | B11: Create tenants table | C11: Sprint 2 | D11: 46158 | E11: 46158 | F11: 1 | G11: Todo | H11: IAM-007 | N11: ■
A12: IAM-011 | B12: Create app_users table | C12: Sprint 2 | D12: 46158 | E12: 46158 | F12: 1 | G12: Todo | H12: IAM-010 | N12: ■
A13: IAM-012 | B13: Create transporter profiles table | C13: Sprint 2 | D13: 46159 | E13: 46159 | F13: 1 | G13: Todo | H13: IAM-010 | O13: ■
A14: IAM-013 | B14: Create car puller profiles table | C14: Sprint 2 | D14: 46159 | E14: 46159 | F14: 1 | G14: Todo | H14: IAM-011 | O14: ■
A15: IAM-014 | B15: Implement tenant RLS policies | C15: Sprint 2 | D15: 46160 | E15: 46161 | F15: 2 | G15: Todo | H15: IAM-010,IAM-011,IAM-012,IAM-013 | P15: ■ | Q15: ■
A16: IAM-015 | B16: Implement register company flow | C16: Sprint 2 | D16: 46160 | E16: 46161 | F16: 2 | G16: Todo | H16: IAM-008,IAM-010,IAM-011 | P16: ■ | Q16: ■
A17: IAM-016 | B17: Implement login flow | C17: Sprint 2 | D17: 46161 | E17: 46162 | F17: 2 | G17: Todo | H17: IAM-008,IAM-011 | Q17: ■ | R17: ■
A18: IAM-017 | B18: Connect login/register UI to API | C18: Sprint 2 | D18: 46162 | E18: 46163 | F18: 2 | G18: Todo | H18: IAM-009,IAM-015,IAM-016 | R18: ■ | S18: ■
A19: IAM-018 | B19: Create auth guard and role guard | C19: Sprint 2 | D19: 46162 | E19: 46163 | F19: 2 | G19: Todo | H19: IAM-016 | R19: ■ | S19: ■
A20: IAM-019 | B20: Create invitations table | C20: Sprint 3 | D20: 46164 | E20: 46164 | F20: 1 | G20: Todo | H20: IAM-014 | T20: ■
A21: IAM-020 | B21: Build invite user API | C21: Sprint 3 | D21: 46164 | E21: 46165 | F21: 2 | G21: Todo | H21: IAM-018,IAM-019 | T21: ■ | U21: ■
A22: IAM-021 | B22: Build accept invitation API | C22: Sprint 3 | D22: 46165 | E22: 46166 | F22: 2 | G22: Todo | H22: IAM-020 | U22: ■ | V22: ■
A23: IAM-022 | B23: Build users list API | C23: Sprint 3 | D23: 46166 | E23: 46166 | F23: 1 | G23: Todo | H23: IAM-018 | V23: ■
A24: IAM-023 | B24: Build user management UI | C24: Sprint 3 | D24: 46167 | E24: 46168 | F24: 2 | G24: Todo | H24: IAM-017,IAM-020,IAM-022 | W24: ■ | X24: ■
A25: IAM-024 | B25: Create dashboard layout | C25: Sprint 3 | D25: 46166 | E25: 46167 | F25: 2 | G25: Todo | H25: IAM-017 | V25: ■ | W25: ■
A26: IAM-025 | B26: Build transporter profile API/UI | C26: Sprint 3 | D26: 46168 | E26: 46169 | F26: 2 | G26: Todo | H26: IAM-012,IAM-018,IAM-024 | X26: ■ | Y26: ■
A27: IAM-026 | B27: Create tasks table | C27: Sprint 4 | D27: 46170 | E27: 46170 | F27: 1 | G27: Todo | H27: IAM-014 | Z27: ■
A28: IAM-027 | B28: Create task status history table | C28: Sprint 4 | D28: 46170 | E28: 46170 | F28: 1 | G28: Todo | H28: IAM-026 | Z28: ■
A29: IAM-028 | B29: Create task DTOs | C29: Sprint 4 | D29: 46171 | E29: 46171 | F29: 1 | G29: Todo | H29: IAM-026 | AA29: ■
A30: IAM-029 | B30: Build create task API | C30: Sprint 4 | D30: 46171 | E30: 46172 | F30: 2 | G30: Todo | H30: IAM-018,IAM-026,IAM-028 | AA30: ■ | AB30: ■
A31: IAM-030 | B31: Build task listing API | C31: Sprint 4 | D31: 46172 | E31: 46173 | F31: 2 | G31: Todo | H31: IAM-029 | AB31: ■ | AC31: ■
A32: IAM-031 | B32: Build task detail API | C32: Sprint 4 | D32: 46173 | E32: 46174 | F32: 2 | G32: Todo | H32: IAM-030 | AC32: ■ | AD32: ■
A33: IAM-032 | B33: Build status transition API | C33: Sprint 4 | D33: 46174 | E33: 46175 | F33: 2 | G33: Todo | H33: IAM-027,IAM-031 | AD33: ■ | AE33: ■
A34: IAM-033 | B34: Build task list page | C34: Sprint 4 | D34: 46173 | E34: 46174 | F34: 2 | G34: Todo | H34: IAM-024,IAM-030 | AC34: ■ | AD34: ■
A35: IAM-034 | B35: Build create task page | C35: Sprint 4 | D35: 46174 | E35: 46176 | F35: 3 | G35: Todo | H35: IAM-023,IAM-029 | AD35: ■ | AE35: ■ | AF35: ■
A36: IAM-035 | B36: Build task detail page | C36: Sprint 4 | D36: 46176 | E36: 46177 | F36: 2 | G36: Todo | H36: IAM-031,IAM-033 | AF36: ■ | AG36: ■
A37: IAM-036 | B37: Create storage buckets and policies | C37: Sprint 5 | D37: 46178 | E37: 46178 | F37: 1 | G37: Todo | H37: IAM-014 | AH37: ■
A38: IAM-037 | B38: Build signed upload URL API | C38: Sprint 5 | D38: 46178 | E38: 46179 | F38: 2 | G38: Todo | H38: IAM-036,IAM-018 | AH38: ■ | AI38: ■
A39: IAM-038 | B39: Build file metadata table/API | C39: Sprint 5 | D39: 46179 | E39: 46180 | F39: 2 | G39: Todo | H39: IAM-037 | AI39: ■ | AJ39: ■
A40: IAM-039 | B40: Build reusable upload component | C40: Sprint 5 | D40: 46180 | E40: 46181 | F40: 2 | G40: Todo | H40: IAM-037 | AJ40: ■ | AK40: ■
...

Sheet Dependencies
A1: Task ID | B1: Task Title | C1: Depends On | D1: Dependency Meaning | E1: Blocking Risk | F1: Ready?
A2: IAM-001 | B2: Initialize Git repositories | D2: No dependency | E2: Low | F2: Done
A3: IAM-002 | B3: Create Next.js app | C3: IAM-001 | D3: Finish dependency before starting this task | E3: Medium | F3: Done
A4: IAM-003 | B4: Create NestJS backend | C4: IAM-001 | D4: Finish dependency before starting this task | E4: Medium | F4: Done
A5: IAM-004 | B5: Configure environment management | C5: IAM-002,IAM-003 | D5: Finish dependency before starting this task | E5: Medium | F5: =IF(COUNTA(C2)=0,"Ready","Check dependency status") -> Ready
A6: IAM-005 | B6: Setup code quality tools | C6: IAM-002,IAM-003 | D6: Finish dependency before starting this task | E6: Medium | F6: =IF(COUNTA(C2)=0,"Ready","Check dependency status") -> Ready
A7: IAM-006 | B7: Create Supabase project | C7: IAM-004 | D7: Finish dependency before starting this task | E7: Medium | F7: =IF(COUNTA(C2)=0,"Ready","Check dependency status") -> Ready
A8: IAM-007 | B8: Create base audit trigger | C8: IAM-006 | D8: Finish dependency before starting this task | E8: Medium | F8: =IF(COUNTA(C2)=0,"Ready","Check dependency status") -> Ready
A9: IAM-008 | B9: Build auth DTOs and validation | C9: IAM-003 | D9: Finish dependency before starting this task | E9: Medium | F9: =IF(COUNTA(C2)=0,"Ready","Check dependency status") -> Ready
A10: IAM-009 | B10: Auth UI shell | C10: IAM-002 | D10: Finish dependency before starting this task | E10: Medium | F10: =IF(COUNTA(C2)=0,"Ready","Check dependency status") -> Ready
A11: IAM-010 | B11: Create tenants table | C11: IAM-007 | D11: Finish dependency before starting this task | E11: Medium | F11: =IF(COUNTA(C2)=0,"Ready","Check dependency status") -> Ready
A12: IAM-011 | B12: Create app_users table | C12: IAM-010 | D12: Finish dependency before starting this task | E12: Medium | F12: =IF(COUNTA(C2)=0,"Ready","Check dependency status") -> Ready
A13: IAM-012 | B13: Create transporter profiles table | C13: IAM-010 | D13: Finish dependency before starting this task | E13: Medium | F13: =IF(COUNTA(C2)=0,"Ready","Check dependency status") -> Ready
A14: IAM-013 | B14: Create car puller profiles table | C14: IAM-011 | D14: Finish dependency before starting this task | E14: Medium | F14: =IF(COUNTA(C2)=0,"Ready","Check dependency status") -> Ready
A15: IAM-014 | B15: Implement tenant RLS policies | C15: IAM-010,IAM-011,IAM-012,IAM-013 | D15: Finish dependency before starting this task | E15: Medium | F15: =IF(COUNTA(C2)=0,"Ready","Check dependency status") -> Ready
A16: IAM-015 | B16: Implement register company flow | C16: IAM-008,IAM-010,IAM-011 | D16: Finish dependency before starting this task | E16: Medium | F16: =IF(COUNTA(C2)=0,"Ready","Check dependency status") -> Ready
A17: IAM-016 | B17: Implement login flow | C17: IAM-008,IAM-011 | D17: Finish dependency before starting this task | E17: Medium | F17: =IF(COUNTA(C2)=0,"Ready","Check dependency status") -> Ready
A18: IAM-017 | B18: Connect login/register UI to API | C18: IAM-009,IAM-015,IAM-016 | D18: Finish dependency before starting this task | E18: Medium | F18: =IF(COUNTA(C2)=0,"Ready","Check dependency status") -> Ready
A19: IAM-018 | B19: Create auth guard and role guard | C19: IAM-016 | D19: Finish dependency before starting this task | E19: Medium | F19: =IF(COUNTA(C2)=0,"Ready","Check dependency status") -> Ready
A20: IAM-019 | B20: Create invitations table | C20: IAM-014 | D20: Finish dependency before starting this task | E20: Medium | F20: =IF(COUNTA(C2)=0,"Ready","Check dependency status") -> Ready
A21: IAM-020 | B21: Build invite user API | C21: IAM-018,IAM-019 | D21: Finish dependency before starting this task | E21: Medium | F21: =IF(COUNTA(C2)=0,"Ready","Check dependency status") -> Ready
A22: IAM-021 | B22: Build accept invitation API | C22: IAM-020 | D22: Finish dependency before starting this task | E22: Medium | F22: =IF(COUNTA(C2)=0,"Ready","Check dependency status") -> Ready
A23: IAM-022 | B23: Build users list API | C23: IAM-018 | D23: Finish dependency before starting this task | E23: Medium | F23: =IF(COUNTA(C2)=0,"Ready","Check dependency status") -> Ready
A24: IAM-023 | B24: Build user management UI | C24: IAM-017,IAM-020,IAM-022 | D24: Finish dependency before starting this task | E24: Medium | F24: =IF(COUNTA(C2)=0,"Ready","Check dependency status") -> Ready
A25: IAM-024 | B25: Create dashboard layout | C25: IAM-017 | D25: Finish dependency before starting this task | E25: Medium | F25: =IF(COUNTA(C2)=0,"Ready","Check dependency status") -> Ready
A26: IAM-025 | B26: Build transporter profile API/UI | C26: IAM-012,IAM-018,IAM-024 | D26: Finish dependency before starting this task | E26: Medium | F26: =IF(COUNTA(C2)=0,"Ready","Check dependency status") -> Ready
A27: IAM-026 | B27: Create tasks table | C27: IAM-014 | D27: Finish dependency before starting this task | E27: Medium | F27: =IF(COUNTA(C2)=0,"Ready","Check dependency status") -> Ready
A28: IAM-027 | B28: Create task status history table | C28: IAM-026 | D28: Finish dependency before starting this task | E28: Medium | F28: =IF(COUNTA(C2)=0,"Ready","Check dependency status") -> Ready
A29: IAM-028 | B29: Create task DTOs | C29: IAM-026 | D29: Finish dependency before starting this task | E29: Medium | F29: =IF(COUNTA(C2)=0,"Ready","Check dependency status") -> Ready
A30: IAM-029 | B30: Build create task API | C30: IAM-018,IAM-026,IAM-028 | D30: Finish dependency before starting this task | E30: Medium | F30: =IF(COUNTA(C2)=0,"Ready","Check dependency status") -> Ready
A31: IAM-030 | B31: Build task listing API | C31: IAM-029 | D31: Finish dependency before starting this task | E31: Medium | F31: =IF(COUNTA(C2)=0,"Ready","Check dependency status") -> Ready
A32: IAM-031 | B32: Build task detail API | C32: IAM-030 | D32: Finish dependency before starting this task | E32: Medium | F32: =IF(COUNTA(C2)=0,"Ready","Check dependency status") -> Ready
A33: IAM-032 | B33: Build status transition API | C33: IAM-027,IAM-031 | D33: Finish dependency before starting this task | E33: Medium | F33: =IF(COUNTA(C2)=0,"Ready","Check dependency status") -> Ready
A34: IAM-033 | B34: Build task list page | C34: IAM-024,IAM-030 | D34: Finish dependency before starting this task | E34: Medium | F34: =IF(COUNTA(C2)=0,"Ready","Check dependency status") -> Ready
A35: IAM-034 | B35: Build create task page | C35: IAM-023,IAM-029 | D35: Finish dependency before starting this task | E35: Medium | F35: =IF(COUNTA(C2)=0,"Ready","Check dependency status") -> Ready
A36: IAM-035 | B36: Build task detail page | C36: IAM-031,IAM-033 | D36: Finish dependency before starting this task | E36: Medium | F36: =IF(COUNTA(C2)=0,"Ready","Check dependency status") -> Ready
A37: IAM-036 | B37: Create storage buckets and policies | C37: IAM-014 | D37: Finish dependency before starting this task | E37: Medium | F37: =IF(COUNTA(C2)=0,"Ready","Check dependency status") -> Ready
A38: IAM-037 | B38: Build signed upload URL API | C38: IAM-036,IAM-018 | D38: Finish dependency before starting this task | E38: Medium | F38: =IF(COUNTA(C2)=0,"Ready","Check dependency status") -> Ready
A39: IAM-038 | B39: Build file metadata table/API | C39: IAM-037 | D39: Finish dependency before starting this task | E39: Medium | F39: =IF(COUNTA(C2)=0,"Ready","Check dependency status") -> Ready
A40: IAM-039 | B40: Build reusable upload component | C40: IAM-037 | D40: Finish dependency before starting this task | E40: Medium | F40: =IF(COUNTA(C2)=0,"Ready","Check dependency status") -> Ready
...

Sheet IntelliJ Coding Tasks
A1: Code | B1: Layer | C1: Module | D1: File / Class | E1: Exact Coding Task | F1: Implementation Notes | G1: Related Jira Task | H1: Acceptance Criteria | I1: Status
A2: CODE-001 | B2: Backend | C2: config | D2: apps/api/src/config/env.config.ts; apps/api/src/app.module.ts; apps/api/.env.example; apps/web/.env.example | E2: Complete environment configuration and validation | F2: Validate required API environment variables and fail clearly during startup when required values are missing or invalid. Keep configuration typed and centralized. Add repository-safe .env.example documentation for required API variables and add frontend public-environment examples or conventions where needed, using the appropriate NEXT_PUBLIC_ prefix for browser-exposed values. Do not add real credentials, tokens, passwords, URLs containing secrets, or production values. Do not provision Supabase or perform database migrations in this task. | G2: IAM-004 | H2: Required API environment values are validated; invalid or missing required values produce a clear startup failure; API and frontend example-environment files document required variables; no secrets are committed; existing development configuration continues to work; TypeScript, lint, and relevant tests pass. | I2: Done
A3: CODE-002 | B3: Backend | C3: auth | D3: apps/api/src/modules/auth/dto/register.dto.ts | E3: Create RegisterDto | F3: Fields: email,password,role,companyName,fullName,phone. Use class-validator. | G3: IAM-008 | H3: Invalid registration payload rejected | I3: Done
A4: CODE-003 | B4: Backend | C4: auth | D4: apps/api/src/modules/auth/dto/login.dto.ts | E4: Create LoginDto | F4: Fields: email,password. | G4: IAM-008 | H4: Invalid login payload rejected | I4: Done
A5: CODE-048 | B5: Backend | C5: auth / supabase | D5: apps/api/src/common/supabase/supabase.constants.ts; apps/api/src/common/supabase/supabase.provider.ts; apps/api/src/common/supabase/supabase.module.ts; apps/api/src/common/supabase/supabase.provider.spec.ts; apps/api/src/modules/auth/auth.types.ts; apps/api/src/modules/auth/dto/auth-response.dto.ts; apps/api/src/modules/auth/dto/register.dto.ts; apps/api/src/modules/auth/auth.module.ts; apps/api/package.json; ././pnpm-lock.yaml | E5: Create authentication integration foundation | F5: Install and configure @supabase/supabase-js and pg for the NestJS API. Create separate injectable Supabase public and admin clients. The public client uses SUPABASE_URL and SUPABASE_ANON_KEY. The admin client uses SUPABASE_URL and SUPABASE_SERVICE_ROLE_KEY and must remain server-only. Read configuration only through ConfigService. Never return, log, serialize, or otherwise expose the service-role key. Define the approved authentication response contract: - session is either null or an object containing accessToken, refreshToken, expiresIn, expiresAt, and tokenType. - requiresEmailConfirmation is boolean. - user contains id, email, tenantId, role, fullName, and phone. Update RegisterDto so registration accepts only email, password, companyName, fullName, and phone. Remove the client-supplied role field. LoginDto remains email and password. Register the providers and authentication types through AuthModule. Add focused unit tests for provider construction, configuration validation, response mapping types, and secret boundaries. Do not implement registration orchestration, login behavior, controllers, database writes, JWT validation, guards, frontend changes, or hosted calls. | G5: IAM-015,IAM-016 | H5: The API package contains @supabase/supabase-js, pg, and required type dependencies. Injectable public and admin Supabase clients are available through Nest dependency injection. The public client uses only the anonymous key and the admin client uses the server-only service-role key. RegisterDto accepts email, password, companyName, fullName, and phone and no longer accepts role. Auth response DTOs represent the approved nullable-session, requiresEmailConfirmation, and user-context contract. Configuration is loaded through ConfigService. No secret value is printed, returned, committed, or exposed to frontend code. Unit tests pass. No Auth user, tenant, app-user, session, controller, RLS policy, frontend, or hosted-project operation is created. | I5: Todo
A6: CODE-005 | B6: Backend | C6: auth | D6: apps/api/src/modules/auth/auth.service.ts; apps/api/src/modules/auth/auth.repository.ts; apps/api/src/modules/auth/auth.service.spec.ts; apps/api/src/modules/auth/auth.repository.spec.ts | E6: Implement company registration orchestration | F6: Implement the registration service using the injectable Supabase clients and a PostgreSQL repository backed by pg and DATABASE_URL. Accept RegisterDto containing email, password, companyName, fullName, and phone. Do not accept or trust a client-supplied role. Assign admin to the first user. Create the Supabase Auth identity through the public sign-up capability and respect the Supabase email-confirmation setting. Then create exactly one tenant and one app_users record in one PostgreSQL transaction. The app_users id equals the Supabase Auth user id and references the new tenant. If the database transaction fails after Auth creation, roll back all database writes and attempt compensating deletion of the Auth identity through the admin client. If compensation fails, log only the orphaned Auth user identifier and a safe internal error; never log keys, passwords, access tokens, refresh tokens, or provider response bodies. Return the approved auth response. When Supabase returns no session because email confirmation is required, return session null and requiresEmailConfirmation true. Map duplicate email or tenant name to 409, provider unavailability to 503, and unexpected or failed-compensation errors to 500. Do not create transporter_profiles, controllers, login behavior, guards, JWT strategy code, RLS policies, frontend code, or hosted operations. | G6: IAM-015 | H6: Successful registration creates exactly one Supabase Auth identity, one tenant, and one linked app_users row with role admin. Tenant and app-user writes occur in one PostgreSQL transaction. The returned response follows the approved session and user-context contract. When email confirmation is required, session is null and requiresEmailConfirmation is true. A database failure leaves no tenant or app_users records and triggers compensating Auth-user deletion. Tests cover successful registration, role derivation, duplicate email, duplicate company name, Auth failure, transaction rollback, successful compensation, failed compensation, confirmation-required responses, session responses, and secret-safe errors. No transporter profile, controller, login implementation, RLS policy, frontend file, hosted database, or hosted Auth operation is modified. | I6: Todo
A7: CODE-049 | B7: Backend | C7: auth | D7: apps/api/src/modules/auth/auth.service.ts; apps/api/src/modules/auth/auth.repository.ts; apps/api/src/modules/auth/auth.service.spec.ts; apps/api/src/modules/auth/auth.repository.spec.ts | E7: Implement login service and user context | F7: Add login behavior to AuthService using the public Supabase client. Authenticate email and password through Supabase Auth. For a successful session, load the linked public.app_users record and return user context containing id, email, tenantId, role, fullName, and phone. Return the approved non-null session object containing accessToken, refreshToken, expiresIn, expiresAt, and tokenType, with requiresEmailConfirmation false. Map invalid credentials to 401. Map a valid Auth identity without a linked app_users profile to 403. Map Supabase availability errors to 503 and unexpected consistency failures to a safe 500. Never use or expose the service-role key for password authentication. Do not implement controllers, JWT strategy, guards, refresh endpoints, logout, frontend integration, RLS policies, or hosted operations. | G7: IAM-016 | H7: Valid credentials return a Supabase session and linked app-user context containing user id, email, tenant id, role, full name, and phone. Invalid credentials return 401 without revealing whether the email exists. A valid Auth identity without an app_users row returns 403. Provider unavailability returns 503. Unexpected failures return a safe 500. Tests cover valid login, invalid credentials, missing profile, session mapping, tenant and role context, provider failure, and absence of secrets in responses and logs. No controller, JWT strategy, guard, registration side effect, frontend file, RLS policy, hosted database, or hosted Auth project is modified. | I7: Todo
A8: CODE-004 | B8: Backend | C8: auth | D8: apps/api/src/modules/auth/auth.controller.ts; apps/api/src/modules/auth/auth.controller.spec.ts | E8: Implement register and login controllers | F8: Implement thin NestJS controller endpoints backed only by AuthService. POST /auth/register accepts RegisterDto, delegates to AuthService.register, and returns the approved AuthResponseDto with HTTP 201. POST /auth/login accepts LoginDto, delegates to AuthService.login, and returns the approved AuthResponseDto with HTTP 200. The controller must not instantiate Supabase clients, access ConfigService, perform database queries, manage transactions, create JWTs, or expose provider errors. Preserve Nest DTO validation and service-level safe exception mappings. Do not modify services, repositories, Supabase providers, JWT strategy, guards, frontend files, RLS policies, or hosted resources. | G8: IAM-015,IAM-016 | H8: POST /auth/register returns HTTP 201 and the AuthService registration response. POST /auth/login returns HTTP 200 and the AuthService login response. Controller tests verify DTO delegation, status codes, response forwarding, and safe propagation of documented HTTP exceptions. The controller contains no Supabase, database, transaction, JWT-signing, or secret-handling logic. | I8: Todo
A9: CODE-006 | B9: Backend | C9: auth | D9: apps/api/src/modules/auth/jwt.strategy.ts | E9: Implement JWT strategy | F9: Validate token, attach user_id, tenant_id, role. | G9: IAM-016 | H9: Protected requests have user context | I9: Todo
A10: CODE-007 | B10: Backend | C10: common | D10: apps/api/src/common/guards/auth.guard.ts | E10: Create auth guard | F10: Reject unauthenticated requests. | G10: IAM-018 | H10: 401 returned without token | I10: Todo
A11: CODE-008 | B11: Backend | C11: common | D11: apps/api/src/common/guards/roles.guard.ts | E11: Create role guard | F11: Allow decorators like @Roles("admin"). | G11: IAM-018 | H11: 403 returned for wrong role | I11: Todo
A12: CODE-009 | B12: Backend | C12: tenants | D12: apps/api/src/modules/tenants/tenants.service.ts | E12: Create tenant service | F12: Create/get current tenant and update company settings. | G12: IAM-025 | H12: Tenant data isolated | I12: Todo
... A50: CODE-047 | B50: Database | C50: migrations | D50: supabase/migrations/20260804234822_create_app_users.sql | E50: Create app_users migration | F50: Create one ordered, timestamped Supabase PostgreSQL migration for public.app_users. Define id as uuid primary key referencing auth.users(id), with no generated default and ON DELETE CASCADE, so each Supabase authentication identity has at most one application profile. Define tenant_id as uuid NOT NULL referencing public.tenants(id) with ON DELETE RESTRICT, modeling one tenant per app user. Define role as text NOT NULL with an exact check constraint allowing only: - admin - dispatcher - car_puller Define full_name and phone as text NOT NULL. Do not duplicate authentication email and do not add status, membership, invitation, or separate profile fields. Add created_at and updated_at as timestamptz NOT NULL DEFAULT now(). Add created_by and updated_by as nullable uuid columns without foreign keys at this stage. Attach a BEFORE UPDATE trigger that executes public.set_updated_at(). Add an index on tenant_id. Enable row-level security, but do not create access policies because app-user and tenant policies belong to IAM-014. Do not modify authentication, API, frontend, invitation, profile, membership, or other application files. Apply and verify only against the local Supabase database. Do not apply the migration to the hosted project. | G50: IAM-011 | H50: The timestamped migration creates public.app_users with id, tenant_id, role, full_name, phone, created_at, updated_at, created_by, and updated_by. id is a uuid primary key referencing auth.users(id), has no generated default, and uses ON DELETE CASCADE. Inserting an app-user requires an existing auth user, and duplicate profiles for one authentication identity are rejected. tenant_id is required, references public.tenants(id), and uses ON DELETE RESTRICT. role is required and accepts only admin, dispatcher, or car_puller. Invalid role values are rejected. full_name and phone are required. created_at and updated_at use timestamptz NOT NULL DEFAULT now(). created_by and updated_by are nullable uuid columns without foreign keys. A BEFORE UPDATE trigger invokes public.set_updated_at(), and updating a profile changes updated_at. An index exists on tenant_id. RLS is enabled without adding IAM-014 access policies. The migration applies successfully to the local Supabase database. Privileged local verification confirms: - A valid linked app-user can be inserted. - An invalid auth-user ID is rejected. - An invalid tenant ID is rejected. - A duplicate auth-user ID is rejected. - An invalid role is rejected. - updated_at advances after an update. No membership, invitation, API, frontend, or unrelated tables or files are created, and no hosted-project migration is applied. | I50: Done

Sheet File-Class Map
A1: Area | B1: Path | C1: Purpose | D1: Primary Related Tasks | E1: Build Order
A2: Backend | B2: apps/api/src/config/env.config.ts; apps/api/src/app.module.ts; apps/api/.env.example; apps/web/.env.example | C2: Complete environment configuration and validation | D2: IAM-004 | E2: CODE-001
A3: Backend | B3: apps/api/src/modules/auth/dto/register.dto.ts | C3: Create RegisterDto | D3: IAM-008 | E3: CODE-002
A4: Backend | B4: apps/api/src/modules/auth/dto/login.dto.ts | C4: Create LoginDto | D4: IAM-008 | E4: CODE-003
A5: Backend | B5: apps/api/src/common/supabase/supabase.constants.ts; apps/api/src/common/supabase/supabase.provider.ts; apps/api/src/common/supabase/supabase.module.ts; apps/api/src/common/supabase/supabase.provider.spec.ts; apps/api/src/modules/auth/auth.types.ts; apps/api/src/modules/auth/dto/auth-response.dto.ts; apps/api/src/modules/auth/dto/register.dto.ts; apps/api/src/modules/auth/auth.module.ts; apps/api/package.json; ././pnpm-lock.yaml | C5: Create authentication integration foundation | D5: IAM-015,IAM-016 | E5: CODE-048
A6: Backend | B6: apps/api/src/modules/auth/auth.service.ts; apps/api/src/modules/auth/auth.repository.ts; apps/api/src/modules/auth/auth.service.spec.ts; apps/api/src/modules/auth/auth.repository.spec.ts | C6: Implement company registration orchestration | D6: IAM-015 | E6: CODE-005
A7: Backend | B7: apps/api/src/modules/auth/auth.service.ts; apps/api/src/modules/auth/auth.repository.ts; apps/api/src/modules/auth/auth.service.spec.ts; apps/api/src/modules/auth/auth.repository.spec.ts | C7: Implement login service and user context | D7: IAM-016 | E7: CODE-049
A8: Backend | B8: apps/api/src/modules/auth/auth.controller.ts; apps/api/src/modules/auth/auth.controller.spec.ts | C8: Implement register and login controllers | D8: IAM-015,IAM-016 | E8: CODE-004
A9: Backend | B9: apps/api/src/modules/auth/jwt.strategy.ts | C9: Implement JWT strategy | D9: IAM-016 | E9: CODE-006
A10: Backend | B10: apps/api/src/common/guards/auth.guard.ts | C10: Create auth guard | D10: IAM-018 | E10: CODE-007
A11: Backend | B11: apps/api/src/common/guards/roles.guard.ts | C11: Create role guard | D11: IAM-018 | E11: CODE-008
A12: Backend | B12: apps/api/src/modules/tenants/tenants.service.ts | C12: Create tenant service | D12: IAM-025 | E12: CODE-009
... A46: Database | B46: supabase/migrations/20260804234822_create_app_users.sql | C46: Create app_users migration | D46: IAM-011 | E46: CODE-047

Sheet API Contracts
A1: Method | B1: Endpoint | C1: Purpose | D1: Role Access | E1: Request Body / Params | F1: Response | G1: Related Tasks
A2: POST | B2: /auth/register | C2: Register new company admin or invited user | D2: Public | E2: email,password,role,company/profile fields | F2: session + user context | G2: IAM-015,IAM-017
A3: POST | B3: /auth/login | C3: Authenticate user | D3: Public | E3: email,password | F3: session + user context | G3: IAM-016,IAM-017
A4: GET | B4: /users | C4: List tenant users | D4: Admin | E4: query: page,search | F4: users[] | G4: IAM-022,IAM-023
A5: POST | B5: /invitations | C5: Invite user to tenant | D5: Admin | E5: email,role | F5: invitation | G5: IAM-020
A6: POST | B6: /invitations/accept | C6: Accept invite | D6: Public/Auth | E6: token,password/profile fields | F6: user joined tenant | G6: IAM-021
A7: GET | B7: /tasks | C7: List tasks by tenant/role | D7: Admin,Dispatcher,Car Puller | E7: status,search,page,date range | F7: tasks[] | G7: IAM-030,IAM-033,IAM-050
A8: POST | B8: /tasks | C8: Create task | D8: Admin,Dispatcher | E8: assignedTo,notes,priority,workOrderFileId | F8: task | G8: IAM-029,IAM-034
A9: GET | B9: /tasks/:id | C9: Get task detail | D9: Tenant user with access | E9: task id | F9: task + updates + history | G9: IAM-031,IAM-035
A10: PATCH | B10: /tasks/:id/status | C10: Update task status | D10: Assigned role/user | E10: status,note | F10: updated task | G10: IAM-032,IAM-043
A11: POST | B11: /uploads/signed-url | C11: Get signed upload URL | D11: Authenticated | E11: fileName,mimeType,size,taskId | F11: signedUrl,filePath | G11: IAM-037,IAM-039
A12: POST | B12: /tasks/:id/updates | C12: Create note/media update | D12: Tenant user with access | E12: type,note,fileIds | F12: task update | G12: IAM-041,IAM-042
... A14: PATCH | B14: /notifications/:id/read | C14: Mark read | D14: Authenticated | E14: id | F14: notification | G14: IAM-046,IAM-047

Sheet DB Schema + RLS
A1: Table | B1: Purpose | C1: Key Columns | D1: Tenant/RLS Rule | E1: Audit Fields | F1: Related Tasks
A2: tenants | B2: Company/tenant container | C2: id,name,status | D2: Admin can access own tenant | E2: created_at,updated_at,created_by,updated_by | F2: IAM-010,IAM-014
A3: app_users | B3: User profile linked to auth.users | C3: id,tenant_id,role,full_name,phone | D3: Users can see tenant users by policy/admin rules | E3: created_at,updated_at,created_by,updated_by | F3: IAM-011,IAM-014
A4: transporter_profiles | B4: Transporter company/dispatch/broker info | C4: tenant_id,company_name,dispatch_name,broker_name | D4: tenant_id = current user tenant | E4: created_at,updated_at,created_by,updated_by | F4: IAM-012,IAM-025
A5: car_puller_profiles | B5: Car puller profile and photo/logo | C5: user_id,tenant_id,photo_url,logo_url | D5: tenant_id = current user tenant | E5: created_at,updated_at,created_by,updated_by | F5: IAM-013
A6: invitations | B6: Tenant user invitation tokens | C6: tenant_id,email,role,token,expires_at,accepted | D6: Admin only create/list; token accept flow | E6: created_at,updated_at,created_by,updated_by | F6: IAM-019-IAM-021
A7: tasks | B7: Work orders/tasks | C7: tenant_id,created_by,assigned_to,status,notes,priority | D7: Tenant users; car puller assigned only | E7: created_at,updated_at,created_by,updated_by | F7: IAM-026-IAM-032
A8: task_status_history | B8: Audit trail of task status changes | C8: task_id,from_status,to_status,changed_by | D8: Via parent task tenant | E8: created_at,created_by | F8: IAM-027,IAM-032
A9: files | B9: Uploaded file metadata | C9: tenant_id,task_id,path,mime_type,size_bytes | D9: tenant-scoped storage path and policy | E9: created_at,updated_at,created_by,updated_by | F9: IAM-038
A10: task_updates | B10: Timeline notes/images/videos | C10: tenant_id,task_id,type,note,file_id | D10: Via task tenant and user access | E10: created_at,updated_at,created_by,updated_by | F10: IAM-040,IAM-041
A11: notifications | B11: User notifications | C11: tenant_id,user_id,type,read_at,payload | D11: user_id = auth.uid() and tenant_id matched | E11: created_at,updated_at | F11: IAM-044-IAM-047
A12: audit_logs | B12: Sensitive business events | C12: tenant_id,actor_id,entity_type,entity_id,action | D12: Admin/security only by tenant | E12: created_at,created_by | F12: IAM-053

Sheet UI Screens
A1: Screen Code | B1: Screen | C1: Route | D1: Role | E1: Purpose | F1: Components | G1: Related Tasks | H1: Status
A2: UI-001 | B2: Login | C2: /login | D2: All | E2: Authenticate existing users | F2: LoginForm | G2: IAM-009,IAM-017 | H2: Todo
A3: UI-002 | B3: Register | C3: /register | D3: All | E3: Register new tenant/admin or car puller | F3: RegisterForm,RoleSelector | G3: IAM-009,IAM-017 | H3: Todo
A4: UI-003 | B4: Dashboard | C4: /dashboard | D4: Admin/Dispatcher | E4: Show KPIs and recent activity | F4: KpiCard,RecentTasks | G4: IAM-048 | H4: Todo
A5: UI-004 | B5: My Tasks | C5: /my-tasks | D5: Car Puller | E5: Show assigned tasks | F5: TaskCard,TaskFilters | G5: IAM-049 | H5: Todo
A6: UI-005 | B6: Task List | C6: /tasks | D6: Admin/Dispatcher | E6: Manage/search all tenant tasks | F6: TaskTable,TaskFilters | G6: IAM-033,IAM-051 | H6: Todo
A7: UI-006 | B7: Create Task | C7: /tasks/new | D7: Admin/Dispatcher | E7: Create work order and assign car puller | F7: CreateTaskForm,FileUploader | G7: IAM-034,IAM-039 | H7: Todo
A8: UI-007 | B8: Task Detail | C8: /tasks/[id] | D8: All with access | E8: View/update task and timeline | F8: TaskDetail,TaskTimeline,StatusActions | G8: IAM-035,IAM-042 | H8: Todo
A9: UI-008 | B9: Execution Screen | C9: /my-tasks/[id] | D9: Car Puller | E9: Mobile-first execution controls | F9: TaskUpdateComposer,StatusActions | G9: IAM-043 | H9: Todo
A10: UI-009 | B10: Users | C10: /users | D10: Admin | E10: Invite/manage tenant users | F10: UserTable,InviteUserModal | G10: IAM-023 | H10: Todo
A11: UI-010 | B11: Company Settings | C11: /settings/company | D11: Admin | E11: Update transporter profile | F11: CompanySettingsForm | G11: IAM-025 | H11: Todo
A12: UI-011 | B12: Notification Bell | C12: Global Topbar | D12: All | E12: Show alerts and read status | F12: NotificationBell | G12: IAM-047 | H12: Todo

Sheet Risks & Decisions
A1: ID | B1: Type | C1: Risk / Decision | D1: Impact | E1: Mitigation / Decision | F1: Owner | G1: Status
A2: R-001 | B2: Risk | C2: Cross-tenant data leak | D2: Critical | E2: Use RLS, backend tenant middleware, automated tests | F2: Security | G2: Open
A3: R-002 | B3: Risk | C3: Large video uploads fail or cost too much | D3: High | E3: Use signed URLs, file limits, compression guidance, storage lifecycle rules | F3: Backend | G3: Open
A4: R-003 | B4: Risk | C4: Unclear payment ownership between transporter and car puller | D4: Medium | E4: Start with manual paid status; design Stripe later | F4: Product | G4: Open
A5: R-004 | B5: Risk | C5: Scope creep before MVP | D5: High | E5: Freeze Sprint 1-8 as MVP; push GPS/payments/realtime to future | F5: Product | G5: Open
A6: D-001 | B6: Decision | C6: Use single database with tenant_id | D6: High | E6: Best MVP balance; use RLS for isolation | F6: Architecture | G6: Accepted
A7: D-002 | B7: Decision | C7: Use timestamptz for all dates | D7: High | E7: Avoid timezone bugs; store UTC, display local | F7: Database | G7: Accepted

Sheet Release Checklist
A1: Area | B1: Checklist Item | C1: Required for MVP? | D1: Owner | E1: Status | F1: Evidence / Link
A2: Security | B2: RLS tested for tenant isolation | C2: Yes | D2: Security | E2: Todo
A3: Auth | B3: Register/login/logout working in production | C3: Yes | D3: Backend | E3: Todo
A4: Tasks | B4: Transporter can create and assign a task | C4: Yes | D4: Fullstack | E4: Todo
A5: Execution | B5: Car puller can accept/start/upload/complete | C5: Yes | D5: Frontend | E5: Todo
A6: Uploads | B6: PDF/image/video uploads work | C6: Yes | D6: Fullstack | E6: Todo
A7: Notifications | B7: Task assignment notification works | C7: No | D7: Fullstack | E7: Todo
A8: Testing | B8: E2E MVP flow passes | C8: Yes | D8: QA | E8: Todo
A9: Deployment | B9: Frontend deployed with prod env vars | C9: Yes | D9: DevOps | E9: Todo
A10: Deployment | B10: Backend deployed with SSL and CORS | C10: Yes | D10: DevOps | E10: Todo
A11: Docs | B11: User guide created | C11: No | D11: Product | E11: Todo
